Workbook

Sheet Students
A1: student_id | B1: full_name | C1: email | D1: phone | E1: city | F1: province | G1: expected_province | H1: mismatch_province | I1: age | J1: device_type | K1: signup_source | L1: signup_date
A2: STU0001 | B2: Danielle Miller | C2: danielle.miller@gmail.com | D2: +27 81 645 3521 | E2: Johannesburg | F2: Eastern Cape | G2: =_xlfn.XLOOKUP(E2,lookup_table!A:A,lookup_table!B:B, "N/A") -> Gauteng | H2: =IF(F2=G2, "Match", "Mismatch") -> Mismatch | I2: 22 | J2: Mobile | K2: WhatsApp | L2: 45657
A3: STU0002 | B3: Angel Cortez | C3: angelcortez92@yahoo.com | D3: Unknown | E3: Polokwane | F3: Free State | G3: =_xlfn.XLOOKUP(E3,lookup_table!A:A,lookup_table!B:B, "N/A") -> Limpopo | H3: =IF(F3=G3, "Match", "Mismatch") -> Mismatch | I3: 43 | J3: Desktop | K3: Organic | L3: 45265
A4: STU0003 | B4: Joshua Freeman | C4: joshua.freeman@gmail.com | D4: +27 97 995 5271 | E4: Durban | F4: Free State | G4: =_xlfn.XLOOKUP(E4,lookup_table!A:A,lookup_table!B:B, "N/A") -> KwaZulu-Natal | H4: =IF(F4=G4, "Match", "Mismatch") -> Mismatch | I4: 45 | J4: Desktop | K4: Google Search | L4: 45611
A5: STU0004 | B5: Jeffrey Chang | C5: jeffreychang91@yahoo.com | D5: +27 81 477 0054 | E5: Cape Town | F5: Free State | G5: =_xlfn.XLOOKUP(E5,lookup_table!A:A,lookup_table!B:B, "N/A") -> Western Cape | H5: =IF(F5=G5, "Match", "Mismatch") -> Mismatch | J5: Desktop | K5: Unknown | L5: 45182
A6: STU0005 | B6: Jill Vaughn | C6: jill.vaughn@gmail.com | D6: Unknown | E6: Cape Town | F6: Eastern Cape | G6: =_xlfn.XLOOKUP(E6,lookup_table!A:A,lookup_table!B:B, "N/A") -> Western Cape | H6: =IF(F6=G6, "Match", "Mismatch") -> Mismatch | I6: 40 | J6: Mobile | K6: Instagram | L6: 45619
A7: STU0006 | B7: Erica Brewer | C7: erica.brewer@gmail.com | D7: +27 18 203 7788 | E7: Polokwane | F7: Eastern Cape | G7: =_xlfn.XLOOKUP(E7,lookup_table!A:A,lookup_table!B:B, "N/A") -> Limpopo | H7: =IF(F7=G7, "Match", "Mismatch") -> Mismatch | I7: 47 | J7: Desktop | K7: Google Search | L7: 45766
A8: STU0007 | B8: Patricia Henry | C8: Unknown | D8: Unknown | E8: Polokwane | F8: KwaZulu-Natal | G8: =_xlfn.XLOOKUP(E8,lookup_table!A:A,lookup_table!B:B, "N/A") -> Limpopo | H8: =IF(F8=G8, "Match", "Mismatch") -> Mismatch | I8: 19 | J8: Desktop | K8: Organic | L8: 45409
A9: STU0008 | B9: Christopher Mcguire | C9: Unknown | D9: Unknown | E9: Nelspruit | F9: North West | G9: =_xlfn.XLOOKUP(E9,lookup_table!A:A,lookup_table!B:B, "N/A") -> Mpumalanga | H9: =IF(F9=G9, "Match", "Mismatch") -> Mismatch | I9: 23 | J9: Mobile | K9: TikTok | L9: 45803
A10: STU0009 | B10: Robert Davis | C10: robertdavis65@yahoo.com | D10: +27 85 054 2357 | E10: Durban | F10: North West | G10: =_xlfn.XLOOKUP(E10,lookup_table!A:A,lookup_table!B:B, "N/A") -> KwaZulu-Natal | H10: =IF(F10=G10, "Match", "Mismatch") -> Mismatch | I10: 25 | J10: Desktop | K10: Facebook Ad | L10: 45308
A11: STU0010 | B11: Anthony Walker | C11: awalker@outlook.com | D11: +27 88 805 9296 | E11: Cape Town | F11: Gauteng | G11: =_xlfn.XLOOKUP(E11,lookup_table!A:A,lookup_table!B:B, "N/A") -> Western Cape | H11: =IF(F11=G11, "Match", "Mismatch") -> Mismatch | I11: 20 | J11: Tablet | K11: TikTok | L11: 45267
A12: STU0011 | B12: Jeffery Holt | C12: Unknown | D12: +27 65 379 4738 | E12: East London | F12: Eastern Cape | G12: =_xlfn.XLOOKUP(E12,lookup_table!A:A,lookup_table!B:B, "N/A") -> Eastern Cape | H12: =IF(F12=G12, "Match", "Mismatch") -> Match | I12: 49 | J12: Desktop | K12: Facebook Ad | L12: 45360
A13: STU0012 | B13: William Torres | C13: williamtorres76@yahoo.com | D13: +27 74 688 6239 | E13: Cape Town | G13: =_xlfn.XLOOKUP(E13,lookup_table!A:A,lookup_table!B:B, "N/A") -> Western Cape | H13: =IF(F13=G13, "Match", "Mismatch") -> Mismatch | I13: 30 | J13: Unknown | K13: Instagram | L13: 45249
A14: STU0013 | B14: Anthony Perkins | C14: anthonyperkins93@yahoo.com | D14: Unknown | E14: Kimberley | F14: Northern Cape | G14: =_xlfn.XLOOKUP(E14,lookup_table!A:A,lookup_table!B:B, "N/A") -> Northern Cape | H14: =IF(F14=G14, "Match", "Mismatch") -> Match | J14: Mobile | K14: Unknown | L14: 45259
A15: STU0014 | B15: James Kennedy | C15: james.kennedy@gmail.com | D15: +27 06 068 5361 | E15: Polokwane | F15: Gauteng | G15: =_xlfn.XLOOKUP(E15,lookup_table!A:A,lookup_table!B:B, "N/A") -> Limpopo | H15: =IF(F15=G15, "Match", "Mismatch") -> Mismatch | I15: 24 | J15: Desktop | K15: Walk-In | L15: 45390
A16: STU0015 | B16: Debra Schmidt | C16: debra.schmidt@gmail.com | D16: +27 20 472 7790 | E16: Cape Town | F16: Western Cape | G16: =_xlfn.XLOOKUP(E16,lookup_table!A:A,lookup_table!B:B, "N/A") -> Western Cape | H16: =IF(F16=G16, "Match", "Mismatch") -> Match | I16: 26 | J16: Tablet | K16: Organic | L16: 46090
A17: STU0016 | B17: Amy Coleman | C17: amy.coleman@gmail.com | D17: +27 98 614 3410 | E17: Port Elizabeth | F17: Northern Cape | G17: =_xlfn.XLOOKUP(E17,lookup_table!A:A,lookup_table!B:B, "N/A") -> Eastern Cape | H17: =IF(F17=G17, "Match", "Mismatch") -> Mismatch | I17: 51 | J17: Mobile | K17: Google Search | L17: 45359
A18: STU0017 | B18: Jeffrey Reese | C18: jeffrey.reese@gmail.com | D18: +27 80 893 2460 | E18: Cape Town | G18: =_xlfn.XLOOKUP(E18,lookup_table!A:A,lookup_table!B:B, "N/A") -> Western Cape | H18: =IF(F18=G18, "Match", "Mismatch") -> Mismatch | I18: 48 | J18: Desktop | K18: Unknown | L18: 45771
A19: STU0018 | B19: Bridget Rivera | C19: bridgetrivera52@yahoo.com | D19: +27 85 188 8880 | E19: Kimberley | F19: Western Cape | G19: =_xlfn.XLOOKUP(E19,lookup_table!A:A,lookup_table!B:B, "N/A") -> Northern Cape | H19: =IF(F19=G19, "Match", "Mismatch") -> Mismatch | J19: Mobile | K19: TikTok | L19: 45525
A20: STU0019 | B20: Lisa Warner | C20: Unknown | D20: +27 05 153 1952 | E20: Cape Town | F20: Northern Cape | G20: =_xlfn.XLOOKUP(E20,lookup_table!A:A,lookup_table!B:B, "N/A") -> Western Cape | H20: =IF(F20=G20, "Match", "Mismatch") -> Mismatch | I20: 20 | J20: Desktop | K20: Referral | L20: 45146
A21: STU0020 | B21: Adam Nelson | C21: anelson@outlook.com | D21: +27 21 704 3030 | E21: Pretoria | F21: KwaZulu-Natal | G21: =_xlfn.XLOOKUP(E21,lookup_table!A:A,lookup_table!B:B, "N/A") -> Gauteng | H21: =IF(F21=G21, "Match", "Mismatch") -> Mismatch | I21: 50 | J21: Desktop | K21: Referral | L21: 45443
A22: STU0021 | B22: Linda King | C22: lking@outlook.com | D22: +27 40 345 0541 | E22: Johannesburg | F22: KwaZulu-Natal | G22: =_xlfn.XLOOKUP(E22,lookup_table!A:A,lookup_table!B:B, "N/A") -> Gauteng | H22: =IF(F22=G22, "Match", "Mismatch") -> Mismatch | I22: 54 | J22: Unknown | K22: TikTok | L22: 45974
A23: STU0022 | B23: Helen Martinez | C23: helen.martinez@gmail.com | D23: +27 27 758 4161 | E23: Cape Town | F23: Free State | G23: =_xlfn.XLOOKUP(E23,lookup_table!A:A,lookup_table!B:B, "N/A") -> Western Cape | H23: =IF(F23=G23, "Match", "Mismatch") -> Mismatch | I23: 37 | J23: Mobile Phone | K23: WhatsApp | L23: 45569
A24: STU0023 | B24: Matthew Lee | C24: matthew.lee@gmail.com | D24: +27 15 447 9627 | E24: Johannesburg | F24: KwaZulu-Natal | G24: =_xlfn.XLOOKUP(E24,lookup_table!A:A,lookup_table!B:B, "N/A") -> Gauteng | H24: =IF(F24=G24, "Match", "Mismatch") -> Mismatch | I24: 53 | J24: Mobile | K24: Facebook Ad | L24: 45483
A25: STU0024 | B25: Eric Wilson | C25: ericwilson88@yahoo.com | D25: +27 01 658 2029 | E25: Cape Town | F25: North West | G25: =_xlfn.XLOOKUP(E25,lookup_table!A:A,lookup_table!B:B, "N/A") -> Western Cape | H25: =IF(F25=G25, "Match", "Mismatch") -> Mismatch | I25: 25 | J25: Mobile Phone | K25: Facebook Ad | L25: 45841
A26: STU0025 | B26: Susan Herrera | C26: susanherrera95@yahoo.com | D26: +27 55 690 9275 | E26: Johannesburg | F26: Eastern Cape | G26: =_xlfn.XLOOKUP(E26,lookup_table!A:A,lookup_table!B:B, "N/A") -> Gauteng | H26: =IF(F26=G26, "Match", "Mismatch") -> Mismatch | I26: 18 | J26: Unknown | K26: Facebook Ad | L26: 45505
A27: STU0026 | B27: Matthew Gill | C27: mgill@outlook.com | D27: +27 65 431 0278 | E27: Pretoria | G27: =_xlfn.XLOOKUP(E27,lookup_table!A:A,lookup_table!B:B, "N/A") -> Gauteng | H27: =IF(F27=G27, "Match", "Mismatch") -> Mismatch | J27: Desktop | K27: Facebook Ad | L27: 45522
A28: STU0027 | B28: Christopher Lopez | C28: christopher.lopez@gmail.com | D28: +27 94 731 2172 | E28: Durban | F28: Free State | G28: =_xlfn.XLOOKUP(E28,lookup_table!A:A,lookup_table!B:B, "N/A") -> KwaZulu-Natal | H28: =IF(F28=G28, "Match", "Mismatch") -> Mismatch | I28: 36 | J28: Mobile Phone | K28: Google Search | L28: 46082
A29: STU0028 | B29: Colin Robinson | C29: colinrobinson33@yahoo.com | D29: +27 88 442 2583 | E29: Johannesburg | F29: North West | G29: =_xlfn.XLOOKUP(E29,lookup_table!A:A,lookup_table!B:B, "N/A") -> Gauteng | H29: =IF(F29=G29, "Match", "Mismatch") -> Mismatch | J29: Desktop | K29: WhatsApp | L29: 44937
A30: STU0029 | B30: Melanie Washington | C30: mwashington@outlook.com | D30: +27 58 957 8291 | E30: Bloemfontein | F30: Free State | G30: =_xlfn.XLOOKUP(E30,lookup_table!A:A,lookup_table!B:B, "N/A") -> Free State | H30: =IF(F30=G30, "Match", "Mismatch") -> Match | I30: 42 | J30: Mobile | K30: TikTok | L30: 44935
A31: STU0030 | B31: Cassandra Hardy | C31: chardy@outlook.com | D31: +27 91 251 7785 | E31: Polokwane | F31: Limpopo | G31: =_xlfn.XLOOKUP(E31,lookup_table!A:A,lookup_table!B:B, "N/A") -> Limpopo | H31: =IF(F31=G31, "Match", "Mismatch") -> Match | I31: 48 | J31: Tablet | K31: Unknown | L31: 45238
A32: STU0031 | B32: Lindsay Bray | C32: lindsay.bray@gmail.com | D32: +27 18 242 2535 | E32: East London | F32: Limpopo | G32: =_xlfn.XLOOKUP(E32,lookup_table!A:A,lookup_table!B:B, "N/A") -> Eastern Cape | H32: =IF(F32=G32, "Match", "Mismatch") -> Mismatch | I32: 35 | J32: Unknown | K32: Google Search | L32: 46136
A33: STU0032 | B33: Jessica Warren | C33: jessica.warren@gmail.com | D33: +27 42 498 1829 | E33: Polokwane | F33: Eastern Cape | G33: =_xlfn.XLOOKUP(E33,lookup_table!A:A,lookup_table!B:B, "N/A") -> Limpopo | H33: =IF(F33=G33, "Match", "Mismatch") -> Mismatch | I33: 47 | J33: Unknown | K33: Facebook Ad | L33: 46130
A34: STU0033 | B34: Amanda Campbell | C34: amandacampbell16@yahoo.com | D34: +27 90 010 9439 | E34: Durban | F34: North West | G34: =_xlfn.XLOOKUP(E34,lookup_table!A:A,lookup_table!B:B, "N/A") -> KwaZulu-Natal | H34: =IF(F34=G34, "Match", "Mismatch") -> Mismatch | I34: 48 | J34: Tablet | K34: Walk-In | L34: 45554
A35: STU0034 | B35: Teresa Garcia | C35: Unknown | D35: +27 73 647 1027 | E35: Johannesburg | F35: Free State | G35: =_xlfn.XLOOKUP(E35,lookup_table!A:A,lookup_table!B:B, "N/A") -> Gauteng | H35: =IF(F35=G35, "Match", "Mismatch") -> Mismatch | I35: 33 | J35: Desktop | K35: Referral | L35: 45553
A36: STU0035 | B36: Nicholas Lee | C36: nicholaslee30@yahoo.com | D36: +27 55 562 5881 | E36: Johannesburg | F36: Eastern Cape | G36: =_xlfn.XLOOKUP(E36,lookup_table!A:A,lookup_table!B:B, "N/A") -> Gauteng | H36: =IF(F36=G36, "Match", "Mismatch") -> Mismatch | I36: 45 | J36: Mobile Phone | K36: Google Search | L36: 45447
A37: STU0036 | B37: Andrea Perez | C37: andrea.perez@gmail.com | D37: Unknown | E37: Polokwane | F37: Limpopo | G37: =_xlfn.XLOOKUP(E37,lookup_table!A:A,lookup_table!B:B, "N/A") -> Limpopo | H37: =IF(F37=G37, "Match", "Mismatch") -> Match | I37: 42 | J37: Unknown | K37: Facebook Ad | L37: 45989
A38: STU0037 | B38: Maria White | C38: Unknown | D38: +27 77 470 1687 | E38: Cape Town | F38: Mpumalanga | G38: =_xlfn.XLOOKUP(E38,lookup_table!A:A,lookup_table!B:B, "N/A") -> Western Cape | H38: =IF(F38=G38, "Match", "Mismatch") -> Mismatch | I38: 45 | J38: Mobile | K38: Google Search | L38: 46157
A39: STU0038 | B39: Christine Smith | C39: Unknown | D39: +27 47 974 8016 | E39: Durban | F39: Western Cape | G39: =_xlfn.XLOOKUP(E39,lookup_table!A:A,lookup_table!B:B, "N/A") -> KwaZulu-Natal | H39: =IF(F39=G39, "Match", "Mismatch") -> Mismatch | J39: Mobile Phone | K39: TikTok | L39: 45244
A40: STU0039 | B40: Michelle Ferguson | C40: michelle.ferguson@gmail.com | D40: +27 60 983 5841 | E40: Cape Town | F40: Western Cape | G40: =_xlfn.XLOOKUP(E40,lookup_table!A:A,lookup_table!B:B, "N/A") -> Western Cape | H40: =IF(F40=G40, "Match", "Mismatch") -> Match | I40: 30 | J40: Mobile | K40: Google Search | L40: 45521
...

Sheet lookup_table
A1: city | B1: province
A2: Johannesburg | B2: Gauteng
A3: Pretoria | B3: Gauteng
A4: Cape Town | B4: Western Cape
A5: Durban | B5: KwaZulu-Natal
A6: East London | B6: Eastern Cape
A7: Bloemfontein | B7: Free State
A8: Polokwane | B8: Limpopo
A9: Kimberley | B9: Northern Cape
A10: Port Elizabeth | B10: Eastern Cape
A11: Nelspruit | B11: Mpumalanga

Sheet Findings
A1: Data Quality Summary - City-Province | E1: Data Quality Summary - Age | H1: Data Quality Summary - phone number | L1: Data Quality Sumary - amount_paid_zar
A2: Total records | B2: =COUNTA(Students!B:B) -> 601 | E2: Invalid ages | F2: =COUNTIF(Students!I:I, "Invalid") -> 0 | H2: valid phone numbers | I2: =COUNTA(Students!D:D) - I3 -> 601 | L2: Normal | M2: =COUNTIF(Enrollments!I:I, "Normal") -> 2306 | N2: =M2/SUM(M2,M3,M4,M5) -> 0.65885714
A3: Matched City-Province Combinations | B3: =COUNTIF(Students!H:H, "Match") -> 71 | E3: Missing ages | F3: =COUNTIF(Students!I:I, "Blank") -> 0 | H3: missing phone numbers | I3: =COUNTIF(Students!D:D, "Blank") -> 0 | L3: Review | M3: =COUNTIF(Enrollments!I:I, "Review") -> 120 | N3: =M3/SUM(M2,M3,M4,M5) -> 0.034285714
A4: Mismatched City-Province Combinations | B4: =COUNTIF(Students!H:H, "Mismatch") -> 529 | E4: Valid ages | F4: =COUNTA(Students!#REF!)- (F3+F2) -> 1 | L4: Zero Amount | M4: =COUNTIF(Enrollments!I:I, "Zero Amount") -> 344 | N4: =M4/SUM(M2,M3,M4,M5) -> 0.098285714
A5: % Matched | B5: =B3/B2 -> 0.11813644 | L5: Unknown | M5: =COUNTIF(Enrollments!I:I, "Unknown") -> 730 | N5: =M5/SUM(M2,M3,M4,M5) -> 0.20857143
A6: % Mismatched | B6: =B4/B2 -> 0.88019967

Sheet Courses
A1: course_id | B1: course_title | C1: category | D1: level | E1: price_zar | F1: duration_weeks | G1: instructor_id | H1: is_active
A2: C001 | B2: Python for Beginners | C2: Mobile Development | D2: Advanced | E2: 799 | F2: 8 | G2: INS023 | H2: Yes
A3: C002 | B3: Advanced SQL for Analysts | C3: Digital Marketing | D3: Intermediate | E3: 0 | F3: 8 | G3: INS019 | H3: Unknown
A4: C003 | B4: Intro to Data Science | C4: Data Science | D4: Advanced | F4: 4 | G4: INS022 | H4: Yes
A5: C004 | B5: Power BI Masterclass | C5: Data Science | D5: Beginner | E5: 999.99 | F5: 6 | G5: INS022 | H5: Yes
A6: C005 | B6: Full Stack Web Development | C6: Data Science | D6: Beginner | E6: 1500 | F6: 6 | G6: INS014 | H6: No
A7: C006 | B7: React.js Fundamentals | C7: Cloud Computing | D7: Beginner | E7: 499 | F7: 6 | G7: INS025 | H7: Yes
A8: C007 | B8: Digital Marketing 101 | C8: Mobile Development | D8: Advanced | E8: 1500 | G8: INS004 | H8: No
A9: C008 | B9: Google Ads Certification | C9: Mobile Development | D9: Beginner | E9: 1200 | F9: 12 | G9: INS023 | H9: Yes
A10: C009 | B10: Graphic Design with Canva | C10: UI/UX Design | D10: Beginner | E10: 1500 | F10: 12 | G10: INS021 | H10: Yes
A11: C010 | B11: Adobe Photoshop Essentials | C11: Cybersecurity | D11: Advanced | E11: 0 | G11: INS021 | H11: Unknown
A12: C011 | B12: Agile Project Management | C12: Graphic Design | D12: Advanced | F12: 10 | G12: INS004 | H12: Yes
A13: C012 | B13: PMP Exam Prep | C13: UI/UX Design | D13: Intermediate | E13: 799 | F13: 4 | G13: INS024 | H13: Yes
A14: C013 | B14: AWS Cloud Practitioner | C14: Cybersecurity | D14: Intermediate | E14: 3000 | F14: 6 | G14: INS024 | H14: Yes
A15: C014 | B15: Azure Fundamentals | C15: Graphic Design | D15: Beginner | E15: 2500 | F15: 4 | G15: INS014 | H15: Yes
A16: C015 | B16: Ethical Hacking Basics | C16: Digital Marketing | D16: Intermediate | E16: 3000 | G16: INS022 | H16: Yes
A17: C016 | B17: Cybersecurity Fundamentals | C17: Business Analysis | D17: Beginner | E17: 1500 | F17: 4 | G17: INS011 | H17: No
A18: C017 | B18: Android App Development | C18: Mobile Development | D18: Intermediate | E18: 2500 | F18: 6 | G18: INS020 | H18: Yes
A19: C018 | B19: Flutter for Mobile Apps | C19: Web Development | D19: Intermediate | E19: 1200 | G19: INS011 | H19: Yes
A20: C019 | B20: Business Analysis Fundamentals | C20: UI/UX Design | D20: Beginner | G20: INS021 | H20: Unknown
A21: C020 | B21: UX Research Methods | C21: Cybersecurity | D21: Beginner | E21: 1500 | F21: 10 | G21: INS011 | H21: No
A22: C021 | B22: Excel for Business | C22: Graphic Design | D22: Advanced | E22: 1500 | G22: INS024 | H22: Yes
A23: C022 | B23: Tableau for Data Viz | C23: Project Management | D23: Advanced | E23: 1200 | F23: 10 | G23: INS006 | H23: Yes
A24: C023 | B24: Machine Learning Basics | C24: Mobile Development | D24: Advanced | F24: 10 | G24: INS025 | H24: No
A25: C024 | B25: JavaScript Essentials | C25: Project Management | D25: Advanced | E25: 0 | F25: 4 | G25: INS023 | H25: No
A26: C025 | B26: Social Media Marketing | C26: Cloud Computing | D26: Intermediate | F26: 10 | G26: INS002 | H26: Unknown
A27: C026 | B27: Content Writing Skills | C27: UI/UX Design | D27: Intermediate | E27: 2500 | F27: 10 | G27: INS015 | H27: No
A28: C027 | B28: Bookkeeping Basics | C28: Graphic Design | D28: Intermediate | E28: 999.99 | F28: 8 | G28: INS024 | H28: No
A29: C028 | B29: Financial Modeling | C29: UI/UX Design | D29: Beginner | E29: 499 | F29: 8 | G29: INS022 | H29: Unknown
A30: C029 | B30: HR Management Essentials | C30: Cybersecurity | D30: Advanced | E30: 1200 | F30: 10 | G30: INS006 | H30: Yes
A31: C030 | B31: Public Speaking Skills | C31: Digital Marketing | D31: Beginner | E31: 799 | F31: 8 | G31: INS004 | H31: Yes

Sheet Instructors
A1: instructor_id | B1: full_name | C1: specialty | D1: years_experience | E1: rating | F1: city
A2: INS001 | B2: Charles Stephenson | C2: Cloud Computing | D2: 15 | E2: 4.1 | F2: Polokwane
A3: INS002 | B3: Debra Gibbs | C3: Graphic Design | D3: 1 | E3: 3.5 | F3: Port Elizabeth
A4: INS003 | B4: Danielle Colon | C4: UI/UX Design | D4: 3 | E4: 3.4 | F4: Johannesburg
A5: INS004 | B5: April Bailey | C5: Data Science | E5: 4.1 | F5: Port Elizabeth
A6: INS005 | B6: Jackie Miller | C6: Mobile Development | D6: 10 | F6: Johannesburg
A7: INS006 | B7: Kirsten Bowen | C7: Data Science | D7: 2 | E7: 4.2 | F7: East London
A8: INS007 | B8: Logan Nguyen | C8: Graphic Design | D8: 1 | E8: 5 | F8: Nelspruit
A9: INS008 | B9: Robert Holloway | C9: Project Management | D9: 2 | E9: 3 | F9: Nelspruit
A10: INS009 | B10: Vincent Thompson | C10: Cybersecurity | D10: 7 | E10: 2.7 | F10: Johannesburg
A11: INS010 | B11: Kimberly Irwin | C11: Business Analysis | D11: 3 | E11: 4.3 | F11: Polokwane
A12: INS011 | B12: Phyllis Rodriguez | C12: Business Analysis | F12: Durban
A13: INS012 | B13: Janet Valdez | C13: UI/UX Design | D13: 2 | E13: 3 | F13: Cape Town
A14: INS013 | B14: Madison Pierce | C14: Data Science | D14: 3 | E14: 4.2 | F14: Cape Town
A15: INS014 | B15: Connie Adams | C15: Business Analysis | E15: 2.8 | F15: Durban
A16: INS015 | B16: Rhonda Mullins | C16: UI/UX Design | D16: 5 | E16: 2.7 | F16: Port Elizabeth
A17: INS016 | B17: David Barber | C17: Web Development | D17: 2 | E17: 3.8 | F17: Bloemfontein
A18: INS017 | B18: Steven Davis | C18: Business Analysis | D18: 3 | E18: 4.9 | F18: Cape Town
A19: INS018 | B19: Cody Huffman | C19: Graphic Design | D19: 7 | F19: East London
A20: INS019 | B20: John Blair | C20: Project Management | E20: 3.7 | F20: Bloemfontein
A21: INS020 | B21: Alisha Martin | C21: Business Analysis | D21: 10 | E21: 3.8 | F21: Johannesburg
A22: INS021 | B22: James Franklin | C22: Data Science | D22: 1 | E22: 3 | F22: Port Elizabeth
A23: INS022 | B23: Benjamin Sanchez | C23: Graphic Design | D23: 3 | E23: 3 | F23: Bloemfontein
A24: INS023 | B24: Tracy Garcia | C24: Project Management | D24: 3 | E24: 3.6 | F24: East London
A25: INS024 | B25: Monica Morton | C25: Project Management | D25: 7 | E25: 4.8 | F25: Polokwane
A26: INS025 | B26: Jamie Smith | C26: Mobile Development | D26: 2 | E26: 4.2 | F26: Johannesburg

Sheet Enrollments
A1: enrollment_id | B1: student_id | C1: course_id | D1: enrollment_date | E1: status | F1: completion_pct | G1: payment_method | H1: amount_paid_zar | I1: payment_flag | J1: student_rating
A2: E00001 | B2: STU0147 | C2: C018 | D2: 46003 | E2: In Progress | F2: 75 | G2: Cash | H2: 1200 | I2: =IF(H2="", "Unknown", IF(H2=0, "Zero Amount", IF(H2<1, "Review", IF(H2>1, "Normal")))) -> Normal | J2: 2
A3: E00002 | B3: STU0382 | C3: C019 | D3: 45934 | E3: Dropped | F3: 20 | G3: Bank Transfer | I3: =IF(H3="", "Unknown", IF(H3=0, "Zero Amount", IF(H3<1, "Review", IF(H3>1, "Normal")))) -> Unknown
A4: E00003 | B4: STU0389 | C4: C001 | D4: 45804 | E4: Completed | F4: 100 | G4: EFT | H4: 591.44 | I4: =IF(H4="", "Unknown", IF(H4=0, "Zero Amount", IF(H4<1, "Review", IF(H4>1, "Normal")))) -> Normal
A5: E00004 | B5: STU0562 | C5: C014 | D5: 45145 | E5: In Progress | F5: 75 | G5: EFT | H5: -2500 | I5: =IF(H5="", "Unknown", IF(H5=0, "Zero Amount", IF(H5<1, "Review", IF(H5>1, "Normal")))) -> Review
A6: E00005 | B6: STU0280 | C6: C005 | D6: 45370 | E6: Completed | G6: Cash | H6: 1500 | I6: =IF(H6="", "Unknown", IF(H6=0, "Zero Amount", IF(H6<1, "Review", IF(H6>1, "Normal")))) -> Normal
A7: E00006 | B7: STU0388 | C7: C004 | D7: 45189 | E7: Dropped | G7: Unknown | H7: 999.99 | I7: =IF(H7="", "Unknown", IF(H7=0, "Zero Amount", IF(H7<1, "Review", IF(H7>1, "Normal")))) -> Normal | J7: 2
A8: E00007 | B8: STU0098 | C8: C017 | D8: 45254 | E8: Completed | G8: EFT | H8: 2500 | I8: =IF(H8="", "Unknown", IF(H8=0, "Zero Amount", IF(H8<1, "Review", IF(H8>1, "Normal")))) -> Normal | J8: 5
A9: E00008 | B9: STU0050 | C9: C006 | D9: 45874 | E9: Cancelled | F9: 5 | G9: Bank Transfer | H9: 499 | I9: =IF(H9="", "Unknown", IF(H9=0, "Zero Amount", IF(H9<1, "Review", IF(H9>1, "Normal")))) -> Normal | J9: 3
A10: E00009 | B10: STU0489 | C10: C019 | D10: 45112 | E10: Completed | G10: Payfast | I10: =IF(H10="", "Unknown", IF(H10=0, "Zero Amount", IF(H10<1, "Review", IF(H10>1, "Normal")))) -> Unknown
A11: E00010 | B11: STU0130 | C11: C005 | D11: 46157 | E11: Completed | G11: EFT | H11: 1500 | I11: =IF(H11="", "Unknown", IF(H11=0, "Zero Amount", IF(H11<1, "Review", IF(H11>1, "Normal")))) -> Normal
A12: E00011 | B12: STU0256 | C12: C022 | D12: 46147 | E12: Cancelled | F12: 20 | G12: EFT | H12: 1200 | I12: =IF(H12="", "Unknown", IF(H12=0, "Zero Amount", IF(H12<1, "Review", IF(H12>1, "Normal")))) -> Normal
A13: E00012 | B13: STU0480 | C13: C017 | D13: 45214 | E13: Completed | G13: Cash | H13: 2500 | I13: =IF(H13="", "Unknown", IF(H13=0, "Zero Amount", IF(H13<1, "Review", IF(H13>1, "Normal")))) -> Normal | J13: 4
A14: E00013 | B14: STU0313 | C14: C021 | D14: 45904 | E14: Completed | G14: EFT | H14: 1500 | I14: =IF(H14="", "Unknown", IF(H14=0, "Zero Amount", IF(H14<1, "Review", IF(H14>1, "Normal")))) -> Normal | J14: 4
A15: E00014 | B15: STU0082 | C15: C003 | D15: 45468 | E15: Completed | F15: 100 | G15: Card | I15: =IF(H15="", "Unknown", IF(H15=0, "Zero Amount", IF(H15<1, "Review", IF(H15>1, "Normal")))) -> Unknown
A16: E00015 | B16: STU0087 | C16: C024 | D16: 45755 | E16: Unknown | G16: Bank Transfer | H16: 0 | I16: =IF(H16="", "Unknown", IF(H16=0, "Zero Amount", IF(H16<1, "Review", IF(H16>1, "Normal")))) -> Zero Amount
A17: E00016 | B17: STU0521 | C17: C030 | D17: 45319 | E17: Dropped | F17: 20 | G17: EFT | H17: 799 | I17: =IF(H17="", "Unknown", IF(H17=0, "Zero Amount", IF(H17<1, "Review", IF(H17>1, "Normal")))) -> Normal | J17: 5
A18: E00017 | B18: STU0416 | C18: C001 | D18: 45624 | E18: Completed | F18: 100 | G18: EFT | H18: 799 | I18: =IF(H18="", "Unknown", IF(H18=0, "Zero Amount", IF(H18<1, "Review", IF(H18>1, "Normal")))) -> Normal
A19: E00018 | B19: STU0251 | C19: C024 | D19: 45714 | E19: Completed | F19: 100 | G19: Payfast | H19: 0 | I19: =IF(H19="", "Unknown", IF(H19=0, "Zero Amount", IF(H19<1, "Review", IF(H19>1, "Normal")))) -> Zero Amount | J19: 4
A20: E00019 | B20: stu0537 | C20: C029 | D20: 45584 | E20: Dropped | F20: 0 | G20: EFT | H20: 1200 | I20: =IF(H20="", "Unknown", IF(H20=0, "Zero Amount", IF(H20<1, "Review", IF(H20>1, "Normal")))) -> Normal | J20: 3
A21: E00020 | B21: STU0053 | C21: C014 | D21: 45276 | E21: Cancelled | F21: 5 | G21: EFT | H21: 1312.91 | I21: =IF(H21="", "Unknown", IF(H21=0, "Zero Amount", IF(H21<1, "Review", IF(H21>1, "Normal")))) -> Normal | J21: 3
A22: E00021 | B22: STU0256 | C22: C027 | D22: 45461 | E22: In Progress | F22: 40 | G22: Card | H22: 999.99 | I22: =IF(H22="", "Unknown", IF(H22=0, "Zero Amount", IF(H22<1, "Review", IF(H22>1, "Normal")))) -> Normal | J22: 2
A23: E00022 | B23: STU0219 | C23: C001 | D23: 45267 | E23: Cancelled | F23: 5 | G23: Card | H23: 799 | I23: =IF(H23="", "Unknown", IF(H23=0, "Zero Amount", IF(H23<1, "Review", IF(H23>1, "Normal")))) -> Normal | J23: 2
A24: E00023 | B24: STU0475 | C24: C029 | D24: 45159 | E24: Unknown | G24: Unknown | H24: 1200 | I24: =IF(H24="", "Unknown", IF(H24=0, "Zero Amount", IF(H24<1, "Review", IF(H24>1, "Normal")))) -> Normal
A25: E00024 | B25: STU0337 | C25: C010 | D25: 45856 | E25: In Progress | F25: 10 | G25: Payfast | H25: 0 | I25: =IF(H25="", "Unknown", IF(H25=0, "Zero Amount", IF(H25<1, "Review", IF(H25>1, "Normal")))) -> Zero Amount | J25: 3
A26: E00025 | B26: STU0412 | C26: C012 | D26: 45785 | E26: In Progress | F26: 55 | G26: Payfast | I26: =IF(H26="", "Unknown", IF(H26=0, "Zero Amount", IF(H26<1, "Review", IF(H26>1, "Normal")))) -> Unknown | J26: 5
A27: E00026 | B27: STU0421 | C27: C004 | D27: 44968 | E27: Completed | F27: 100 | G27: Card | H27: 999.99 | I27: =IF(H27="", "Unknown", IF(H27=0, "Zero Amount", IF(H27<1, "Review", IF(H27>1, "Normal")))) -> Normal
A28: E00027 | B28: STU0232 | C28: C016 | D28: 45973 | E28: In Progress | F28: 40 | G28: Payfast | H28: 1500 | I28: =IF(H28="", "Unknown", IF(H28=0, "Zero Amount", IF(H28<1, "Review", IF(H28>1, "Normal")))) -> Normal | J28: 3
A29: E00028 | B29: STU0550 | C29: C026 | D29: 45240 | E29: In Progress | F29: 55 | G29: EFT | H29: 2500 | I29: =IF(H29="", "Unknown", IF(H29=0, "Zero Amount", IF(H29<1, "Review", IF(H29>1, "Normal")))) -> Normal | J29: 5
A30: E00029 | B30: STU0445 | C30: C001 | D30: 45601 | E30: Completed | F30: 100 | G30: Card | H30: 514.55 | I30: =IF(H30="", "Unknown", IF(H30=0, "Zero Amount", IF(H30<1, "Review", IF(H30>1, "Normal")))) -> Normal
A31: E00030 | B31: STU0137 | C31: C013 | D31: 45658 | E31: In Progress | F31: 10 | G31: Unknown | H31: 3000 | I31: =IF(H31="", "Unknown", IF(H31=0, "Zero Amount", IF(H31<1, "Review", IF(H31>1, "Normal")))) -> Normal
A32: E00031 | B32: STU0273 | C32: C004 | D32: 46014 | E32: Unknown | G32: Payfast | H32: 999.99 | I32: =IF(H32="", "Unknown", IF(H32=0, "Zero Amount", IF(H32<1, "Review", IF(H32>1, "Normal")))) -> Normal | J32: 5
A33: E00032 | B33: STU0333 | C33: C025 | D33: 45253 | E33: Cancelled | F33: 5 | G33: Card | I33: =IF(H33="", "Unknown", IF(H33=0, "Zero Amount", IF(H33<1, "Review", IF(H33>1, "Normal")))) -> Unknown
A34: E00033 | B34: STU0130 | C34: C005 | D34: 46097 | E34: Completed | F34: 100 | G34: EFT | H34: 1500 | I34: =IF(H34="", "Unknown", IF(H34=0, "Zero Amount", IF(H34<1, "Review", IF(H34>1, "Normal")))) -> Normal | J34: 1
A35: E00034 | B35: STU0440 | C35: C020 | D35: 45124 | E35: Completed | F35: 100 | G35: Card | H35: 1500 | I35: =IF(H35="", "Unknown", IF(H35=0, "Zero Amount", IF(H35<1, "Review", IF(H35>1, "Normal")))) -> Normal | J35: 4
A36: E00035 | B36: STU0498 | C36: C003 | D36: 45301 | E36: Completed | F36: 100 | G36: Payfast | I36: =IF(H36="", "Unknown", IF(H36=0, "Zero Amount", IF(H36<1, "Review", IF(H36>1, "Normal")))) -> Unknown | J36: 4
A37: E00036 | B37: STU0256 | C37: C009 | D37: 45259 | E37: Completed | G37: Bank Transfer | H37: 1500 | I37: =IF(H37="", "Unknown", IF(H37=0, "Zero Amount", IF(H37<1, "Review", IF(H37>1, "Normal")))) -> Normal | J37: 1
A38: E00037 | B38: STU0204 | C38: C016 | D38: 45816 | E38: In Progress | F38: 75 | G38: Cash | H38: -1500 | I38: =IF(H38="", "Unknown", IF(H38=0, "Zero Amount", IF(H38<1, "Review", IF(H38>1, "Normal")))) -> Review | J38: 5
A39: E00038 | B39: STU0004 | C39: C021 | D39: 45345 | E39: Dropped | F39: 5 | G39: Card | H39: 1500 | I39: =IF(H39="", "Unknown", IF(H39=0, "Zero Amount", IF(H39<1, "Review", IF(H39>1, "Normal")))) -> Normal
A40: E00039 | B40: STU0281 | C40: C007 | D40: 46061 | E40: Cancelled | F40: 0 | G40: Card | H40: 1500 | I40: =IF(H40="", "Unknown", IF(H40=0, "Zero Amount", IF(H40<1, "Review", IF(H40>1, "Normal")))) -> Normal | J40: 4
...

Sheet Reviews
A1: review_id | B1: enrollment_id | C1: student_id | D1: course_id | E1: review_rating | F1: review_text | G1: review_date
A2: R00001 | B2: E03241 | C2: STU0204 | D2: C021 | E2: 5 | F2: Excellent value for money | G2: 46106
A3: R00002 | B3: E02576 | C3: STU0383 | D3: C028 | E3: 3 | F3: Unknown | G3: 46125
A4: R00003 | B4: E02542 | C4: STU0065 | D4: C014 | E4: 5 | F4: Too fast paced for beginners | G4: 46115
A5: R00004 | B5: E01609 | C5: STU0107 | D5: C025 | E5: 5 | F5: Great course, learned a lot! | G5: 45698
A6: R00005 | B6: E02348 | C6: STU0422 | D6: C014 | F6: Support team was very responsive | G6: 45524
A7: R00006 | B7: E02515 | C7: STU0548 | D7: C018 | E7: 2 | F7: Content felt outdated | G7: 45588
A8: R00007 | B8: E01100 | C8: STU0144 | D8: C024 | E8: 4 | F8: Best course I've taken on LearnSphere | G8: 45225
A9: R00008 | B9: E02409 | C9: STU0497 | D9: C022 | F9: Unknown | G9: 45705
A10: R00009 | B10: E03336 | C10: STU0024 | D10: C001 | E10: 5 | F10: Loved the practical examples | G10: 45468
A11: R00010 | B11: E00675 | C11: STU0583 | D11: C007 | F11: Instructor was not very clear | G11: 45498
A12: R00011 | B12: E00434 | C12: STU0184 | D12: C006 | E12: 5 | F12: Support team was very responsive | G12: 45360
A13: R00012 | B13: E02656 | C13: STU0391 | D13: C014 | E13: 2 | F13: Content felt outdated | G13: 45994
A14: R00013 | B14: E02636 | C14: STU0367 | D14: C009 | E14: 4 | F14: Support team was very responsive | G14: 45304
A15: R00014 | B15: E02774 | C15: STU0497 | D15: C030 | E15: 1 | F15: 5 stars!!! | G15: 45541
A16: R00015 | B16: E01072 | C16: STU0055 | D16: C004 | F16: Average experience | G16: 45490
A17: R00016 | B17: E02880 | C17: STU0513 | D17: C015 | E17: 5 | F17: Support team was very responsive | G17: 46102
A18: R00017 | B18: E03360 | C18: STU0238 | D18: C016 | E18: 5 | F18: Great course, learned a lot! | G18: 46107
A19: R00018 | B19: E02779 | C19: STU0284 | D19: C003 | E19: 4 | F19: Support team was very responsive | G19: 45986
A20: R00019 | B20: E02453 | C20: STU0384 | D20: C007 | E20: 5 | F20: Content felt outdated | G20: 46094
A21: R00020 | B21: E00125 | C21: STU0064 | D21: C030 | F21: Needs more hands-on exercises | G21: 45873
A22: R00021 | B22: E02854 | C22: STU0062 | D22: C029 | F22: Support team was very responsive | G22: 46017
A23: R00022 | B23: E02728 | C23: STU0060 | D23: C026 | E23: 3 | F23: Too fast paced for beginners | G23: 45206
A24: R00023 | B24: E01220 | C24: STU0491 | D24: C008 | F24: Unknown | G24: 45667
A25: R00024 | B25: E01127 | C25: STU0556 | D25: C014 | E25: 1 | F25: Needs more hands-on exercises | G25: 45825
A26: R00025 | B26: E02821 | C26: STU0419 | D26: C013 | E26: 4 | F26: Too fast paced for beginners | G26: 45449
A27: R00026 | B27: E00939 | C27: STU0524 | D27: C004 | E27: 5 | F27: 5 stars!!! | G27: 45675
A28: R00027 | B28: E00876 | C28: STU0461 | D28: C028 | E28: 1 | F28: Loved the practical examples | G28: 45728
A29: R00028 | B29: E00052 | C29: STU0297 | D29: C002 | F29: Excellent value for money | G29: 45680
A30: R00029 | B30: E02408 | C30: STU0250 | D30: C023 | E30: 3 | F30: 5 stars!!! | G30: 45530
A31: R00030 | B31: E00893 | C31: STU0591 | D31: C018 | E31: 3 | F31: Average experience | G31: 45871
A32: R00031 | B32: E00256 | C32: STU0394 | D32: C025 | E32: 5 | F32: Instructor was not very clear | G32: 45318
A33: R00032 | B33: E03396 | C33: STU0209 | D33: C018 | E33: 1 | F33: Instructor was not very clear | G33: 45449
A34: R00033 | B34: E01350 | C34: STU0555 | D34: C011 | E34: 4 | F34: Unknown | G34: 45588
A35: R00034 | B35: E01113 | C35: STU0526 | D35: C006 | E35: 5 | F35: Not worth the price tbh | G35: 45315
A36: R00035 | B36: E01327 | C36: STU0268 | D36: C009 | E36: 2 | F36: Instructor was not very clear | G36: 46132
A37: R00036 | B37: E02699 | C37: STU0488 | D37: C013 | E37: 3 | F37: Support team was very responsive | G37: 45565
A38: R00037 | B38: E01376 | C38: STU0323 | D38: C006 | E38: 4 | F38: Not worth the price tbh | G38: 45545
A39: R00038 | B39: E03284 | C39: STU0426 | D39: C016 | E39: 1 | F39: Too fast paced for beginners | G39: 45188
A40: R00039 | B40: E02170 | C40: STU0482 | D40: C028 | E40: 2 | F40: Needs more hands-on exercises | G40: 45124
...
